Workbook

Sheet SO-DIMM-i5
A1: Function | B1: Top-Pin | C1: Bank | D1: CLK | E1: CLK | F1: Bank | G1: Bot-Pin | H1: Function | K1: Clocks
A2: GND | B2: 1 | C2: =_xlfn.XLOOKUP(B2,'FPGA-SC-02033-2-0-ECP5U-25-Pino'!I:I,'FPGA-SC-02033-2-0-ECP5U-25-Pino'!C:C,"") | D2: =COUNTIF(K:K,A2) -> 0 | E2: =COUNTIF(K:K,H2) -> 0 | F2: =_xlfn.XLOOKUP(G2,'FPGA-SC-02033-2-0-ECP5U-25-Pino'!I:I,'FPGA-SC-02033-2-0-ECP5U-25-Pino'!C:C,"") | G2: 2 | H2: 5V | I2: =D2+E2 -> 0 | K2: H4
A3: GND | B3: 3 | C3: =_xlfn.XLOOKUP(B3,'FPGA-SC-02033-2-0-ECP5U-25-Pino'!I:I,'FPGA-SC-02033-2-0-ECP5U-25-Pino'!C:C,"") | D3: =COUNTIF(K:K,A3) -> 0 | E3: =COUNTIF(K:K,H3) -> 0 | F3: =_xlfn.XLOOKUP(G3,'FPGA-SC-02033-2-0-ECP5U-25-Pino'!I:I,'FPGA-SC-02033-2-0-ECP5U-25-Pino'!C:C,"") | G3: 4 | H3: 5V | I3: =D3+E3 -> 0 | K3: H5
A4: GND | B4: 5 | C4: =_xlfn.XLOOKUP(B4,'FPGA-SC-02033-2-0-ECP5U-25-Pino'!I:I,'FPGA-SC-02033-2-0-ECP5U-25-Pino'!C:C,"") | D4: =COUNTIF(K:K,A4) -> 0 | E4: =COUNTIF(K:K,H4) -> 0 | F4: =_xlfn.XLOOKUP(G4,'FPGA-SC-02033-2-0-ECP5U-25-Pino'!I:I,'FPGA-SC-02033-2-0-ECP5U-25-Pino'!C:C,"") | G4: 6 | H4: 5V | I4: =D4+E4 -> 0 | K4: G3
A5: GND | B5: 7 | C5: =_xlfn.XLOOKUP(B5,'FPGA-SC-02033-2-0-ECP5U-25-Pino'!I:I,'FPGA-SC-02033-2-0-ECP5U-25-Pino'!C:C,"") | D5: =COUNTIF(K:K,A5) -> 0 | E5: =COUNTIF(K:K,H5) -> 0 | F5: =_xlfn.XLOOKUP(G5,'FPGA-SC-02033-2-0-ECP5U-25-Pino'!I:I,'FPGA-SC-02033-2-0-ECP5U-25-Pino'!C:C,"") | G5: 8 | H5: 5V | I5: =D5+E5 -> 0 | K5: F2
A6: GND | B6: 9 | C6: =_xlfn.XLOOKUP(B6,'FPGA-SC-02033-2-0-ECP5U-25-Pino'!I:I,'FPGA-SC-02033-2-0-ECP5U-25-Pino'!C:C,"") | D6: =COUNTIF(K:K,A6) -> 0 | E6: =COUNTIF(K:K,H6) -> 0 | F6: =_xlfn.XLOOKUP(G6,'FPGA-SC-02033-2-0-ECP5U-25-Pino'!I:I,'FPGA-SC-02033-2-0-ECP5U-25-Pino'!C:C,"") | G6: 10 | H6: 5V | I6: =D6+E6 -> 0 | K6: F3
A7: GND | B7: 11 | C7: =_xlfn.XLOOKUP(B7,'FPGA-SC-02033-2-0-ECP5U-25-Pino'!I:I,'FPGA-SC-02033-2-0-ECP5U-25-Pino'!C:C,"") | D7: =COUNTIF(K:K,A7) -> 0 | E7: =COUNTIF(K:K,H7) -> 0 | F7: =_xlfn.XLOOKUP(G7,'FPGA-SC-02033-2-0-ECP5U-25-Pino'!I:I,'FPGA-SC-02033-2-0-ECP5U-25-Pino'!C:C,"") | G7: 12 | H7: 5V | I7: =D7+E7 -> 0 | K7: E2
A8: NC | B8: 13 | C8: =_xlfn.XLOOKUP(B8,'FPGA-SC-02033-2-0-ECP5U-25-Pino'!I:I,'FPGA-SC-02033-2-0-ECP5U-25-Pino'!C:C,"") | D8: =COUNTIF(K:K,A8) -> 0 | E8: =COUNTIF(K:K,H8) -> 0 | F8: =_xlfn.XLOOKUP(G8,'FPGA-SC-02033-2-0-ECP5U-25-Pino'!I:I,'FPGA-SC-02033-2-0-ECP5U-25-Pino'!C:C,"") | G8: 14 | H8: NC | I8: =D8+E8 -> 0 | K8: F1
A9: ETH1_1P | B9: 15 | C9: =_xlfn.XLOOKUP(B9,'FPGA-SC-02033-2-0-ECP5U-25-Pino'!I:I,'FPGA-SC-02033-2-0-ECP5U-25-Pino'!C:C,"") | D9: =COUNTIF(K:K,A9) -> 0 | E9: =COUNTIF(K:K,H9) -> 0 | F9: =_xlfn.XLOOKUP(G9,'FPGA-SC-02033-2-0-ECP5U-25-Pino'!I:I,'FPGA-SC-02033-2-0-ECP5U-25-Pino'!C:C,"") | G9: 16 | H9: ETH2_1P | I9: =D9+E9 -> 0 | K9: J4
A10: ETH1_1N | B10: 17 | C10: =_xlfn.XLOOKUP(B10,'FPGA-SC-02033-2-0-ECP5U-25-Pino'!I:I,'FPGA-SC-02033-2-0-ECP5U-25-Pino'!C:C,"") | D10: =COUNTIF(K:K,A10) -> 0 | E10: =COUNTIF(K:K,H10) -> 0 | F10: =_xlfn.XLOOKUP(G10,'FPGA-SC-02033-2-0-ECP5U-25-Pino'!I:I,'FPGA-SC-02033-2-0-ECP5U-25-Pino'!C:C,"") | G10: 18 | H10: ETH2_1N | I10: =D10+E10 -> 0 | K10: L18
A11: NC | B11: 19 | C11: =_xlfn.XLOOKUP(B11,'FPGA-SC-02033-2-0-ECP5U-25-Pino'!I:I,'FPGA-SC-02033-2-0-ECP5U-25-Pino'!C:C,"") | D11: =COUNTIF(K:K,A11) -> 0 | E11: =COUNTIF(K:K,H11) -> 0 | F11: =_xlfn.XLOOKUP(G11,'FPGA-SC-02033-2-0-ECP5U-25-Pino'!I:I,'FPGA-SC-02033-2-0-ECP5U-25-Pino'!C:C,"") | G11: 20 | H11: NC | I11: =D11+E11 -> 0 | K11: L20
A12: ETH1_2N | B12: 21 | C12: =_xlfn.XLOOKUP(B12,'FPGA-SC-02033-2-0-ECP5U-25-Pino'!I:I,'FPGA-SC-02033-2-0-ECP5U-25-Pino'!C:C,"") | D12: =COUNTIF(K:K,A12) -> 0 | E12: =COUNTIF(K:K,H12) -> 0 | F12: =_xlfn.XLOOKUP(G12,'FPGA-SC-02033-2-0-ECP5U-25-Pino'!I:I,'FPGA-SC-02033-2-0-ECP5U-25-Pino'!C:C,"") | G12: 22 | H12: ETH2_2N | I12: =D12+E12 -> 0 | K12: K20
A13: ETH1_2P | B13: 23 | C13: =_xlfn.XLOOKUP(B13,'FPGA-SC-02033-2-0-ECP5U-25-Pino'!I:I,'FPGA-SC-02033-2-0-ECP5U-25-Pino'!C:C,"") | D13: =COUNTIF(K:K,A13) -> 0 | E13: =COUNTIF(K:K,H13) -> 0 | F13: =_xlfn.XLOOKUP(G13,'FPGA-SC-02033-2-0-ECP5U-25-Pino'!I:I,'FPGA-SC-02033-2-0-ECP5U-25-Pino'!C:C,"") | G13: 24 | H13: ETH2_2P | I13: =D13+E13 -> 0 | K13: K19
... A17: NC | B17: 31 | C17: =_xlfn.XLOOKUP(B17,'FPGA-SC-02033-2-0-ECP5U-25-Pino'!I:I,'FPGA-SC-02033-2-0-ECP5U-25-Pino'!C:C,"") | D17: =COUNTIF(K:K,A17) -> 0 | E17: =COUNTIF(K:K,H17) -> 0 | F17: =_xlfn.XLOOKUP(G17,'FPGA-SC-02033-2-0-ECP5U-25-Pino'!I:I,'FPGA-SC-02033-2-0-ECP5U-25-Pino'!C:C,"") | G17: 32 | H17: NC | I17: =D17+E17 -> 0 | K17: G19
A18: ETH1_4N | B18: 33 | C18: =_xlfn.XLOOKUP(B18,'FPGA-SC-02033-2-0-ECP5U-25-Pino'!I:I,'FPGA-SC-02033-2-0-ECP5U-25-Pino'!C:C,"") | D18: =COUNTIF(K:K,A18) -> 0 | E18: =COUNTIF(K:K,H18) -> 0 | F18: =_xlfn.XLOOKUP(G18,'FPGA-SC-02033-2-0-ECP5U-25-Pino'!I:I,'FPGA-SC-02033-2-0-ECP5U-25-Pino'!C:C,"") | G18: 34 | H18: ETH2_4N | I18: =D18+E18 -> 0
A19: ETH1_4P | B19: 35 | C19: =_xlfn.XLOOKUP(B19,'FPGA-SC-02033-2-0-ECP5U-25-Pino'!I:I,'FPGA-SC-02033-2-0-ECP5U-25-Pino'!C:C,"") | D19: =COUNTIF(K:K,A19) -> 0 | E19: =COUNTIF(K:K,H19) -> 0 | F19: =_xlfn.XLOOKUP(G19,'FPGA-SC-02033-2-0-ECP5U-25-Pino'!I:I,'FPGA-SC-02033-2-0-ECP5U-25-Pino'!C:C,"") | G19: 36 | H19: ETH2_4P | I19: =D19+E19 -> 0
A20: NC | B20: 37 | C20: =_xlfn.XLOOKUP(B20,'FPGA-SC-02033-2-0-ECP5U-25-Pino'!I:I,'FPGA-SC-02033-2-0-ECP5U-25-Pino'!C:C,"") | D20: =COUNTIF(K:K,A20) -> 0 | E20: =COUNTIF(K:K,H20) -> 0 | F20: =_xlfn.XLOOKUP(G20,'FPGA-SC-02033-2-0-ECP5U-25-Pino'!I:I,'FPGA-SC-02033-2-0-ECP5U-25-Pino'!C:C,"") | G20: 38 | H20: NC | I20: =D20+E20 -> 0
A21: GND | B21: 39 | C21: =_xlfn.XLOOKUP(B21,'FPGA-SC-02033-2-0-ECP5U-25-Pino'!I:I,'FPGA-SC-02033-2-0-ECP5U-25-Pino'!C:C,"") | D21: =COUNTIF(K:K,A21) -> 0 | E21: =COUNTIF(K:K,H21) -> 0 | F21: =_xlfn.XLOOKUP(G21,'FPGA-SC-02033-2-0-ECP5U-25-Pino'!I:I,'FPGA-SC-02033-2-0-ECP5U-25-Pino'!C:C,"") | G21: 40 | H21: GND | I21: =D21+E21 -> 0
I22: =D22+E22 -> 0
I23: =D23+E23 -> 0
A24: U16 | B24: 41 | C24: =_xlfn.XLOOKUP(B24,'FPGA-SC-02033-2-0-ECP5U-25-Pino'!I:I,'FPGA-SC-02033-2-0-ECP5U-25-Pino'!C:C,"") -> 3 | D24: =COUNTIF(K:K,A24) -> 0 | E24: =COUNTIF(K:K,H24) -> 0 | F24: =_xlfn.XLOOKUP(G24,'FPGA-SC-02033-2-0-ECP5U-25-Pino'!I:I,'FPGA-SC-02033-2-0-ECP5U-25-Pino'!C:C,"") -> 8 | G24: 42 | H24: R1 | I24: =D24+E24 -> 0
A25: NC | B25: 43 | C25: =_xlfn.XLOOKUP(B25,'FPGA-SC-02033-2-0-ECP5U-25-Pino'!I:I,'FPGA-SC-02033-2-0-ECP5U-25-Pino'!C:C,"") | D25: =COUNTIF(K:K,A25) -> 0 | E25: =COUNTIF(K:K,H25) -> 0 | F25: =_xlfn.XLOOKUP(G25,'FPGA-SC-02033-2-0-ECP5U-25-Pino'!I:I,'FPGA-SC-02033-2-0-ECP5U-25-Pino'!C:C,"") -> 8 | G25: 44 | H25: T1 | I25: =D25+E25 -> 0
A26: NC | B26: 45 | C26: =_xlfn.XLOOKUP(B26,'FPGA-SC-02033-2-0-ECP5U-25-Pino'!I:I,'FPGA-SC-02033-2-0-ECP5U-25-Pino'!C:C,"") | D26: =COUNTIF(K:K,A26) -> 0 | E26: =COUNTIF(K:K,H26) -> 0 | F26: =_xlfn.XLOOKUP(G26,'FPGA-SC-02033-2-0-ECP5U-25-Pino'!I:I,'FPGA-SC-02033-2-0-ECP5U-25-Pino'!C:C,"") -> 8 | G26: 46 | H26: U1 | I26: =D26+E26 -> 0
A27: NC | B27: 47 | C27: =_xlfn.XLOOKUP(B27,'FPGA-SC-02033-2-0-ECP5U-25-Pino'!I:I,'FPGA-SC-02033-2-0-ECP5U-25-Pino'!C:C,"") | D27: =COUNTIF(K:K,A27) -> 0 | E27: =COUNTIF(K:K,H27) -> 0 | F27: =_xlfn.XLOOKUP(G27,'FPGA-SC-02033-2-0-ECP5U-25-Pino'!I:I,'FPGA-SC-02033-2-0-ECP5U-25-Pino'!C:C,"") -> 8 | G27: 48 | H27: Y2 | I27: =D27+E27 -> 0
A28: K18 | B28: 49 | C28: =_xlfn.XLOOKUP(B28,'FPGA-SC-02033-2-0-ECP5U-25-Pino'!I:I,'FPGA-SC-02033-2-0-ECP5U-25-Pino'!C:C,"") -> 2 | D28: =COUNTIF(K:K,A28) -> 0 | E28: =COUNTIF(K:K,H28) -> 0 | F28: =_xlfn.XLOOKUP(G28,'FPGA-SC-02033-2-0-ECP5U-25-Pino'!I:I,'FPGA-SC-02033-2-0-ECP5U-25-Pino'!C:C,"") -> 8 | G28: 50 | H28: W1 | I28: =D28+E28 -> 0
A29: C18 | B29: 51 | C29: =_xlfn.XLOOKUP(B29,'FPGA-SC-02033-2-0-ECP5U-25-Pino'!I:I,'FPGA-SC-02033-2-0-ECP5U-25-Pino'!C:C,"") -> 2 | D29: =COUNTIF(K:K,A29) -> 0 | E29: =COUNTIF(K:K,H29) -> 0 | F29: =_xlfn.XLOOKUP(G29,'FPGA-SC-02033-2-0-ECP5U-25-Pino'!I:I,'FPGA-SC-02033-2-0-ECP5U-25-Pino'!C:C,"") -> 8 | G29: 52 | H29: V1 | I29: =D29+E29 -> 0
A30: NC | B30: 53 | C30: =_xlfn.XLOOKUP(B30,'FPGA-SC-02033-2-0-ECP5U-25-Pino'!I:I,'FPGA-SC-02033-2-0-ECP5U-25-Pino'!C:C,"") | D30: =COUNTIF(K:K,A30) -> 0 | E30: =COUNTIF(K:K,H30) -> 0 | F30: =_xlfn.XLOOKUP(G30,'FPGA-SC-02033-2-0-ECP5U-25-Pino'!I:I,'FPGA-SC-02033-2-0-ECP5U-25-Pino'!C:C,"") -> 6 | G30: 54 | H30: M1 | I30: =D30+E30 -> 0
A31: GND | B31: 55 | C31: =_xlfn.XLOOKUP(B31,'FPGA-SC-02033-2-0-ECP5U-25-Pino'!I:I,'FPGA-SC-02033-2-0-ECP5U-25-Pino'!C:C,"") | D31: =COUNTIF(K:K,A31) -> 0 | E31: =COUNTIF(K:K,H31) -> 0 | F31: =_xlfn.XLOOKUP(G31,'FPGA-SC-02033-2-0-ECP5U-25-Pino'!I:I,'FPGA-SC-02033-2-0-ECP5U-25-Pino'!C:C,"") | G31: 56 | H31: GND | I31: =D31+E31 -> 0
A32: T18 | B32: 57 | C32: =_xlfn.XLOOKUP(B32,'FPGA-SC-02033-2-0-ECP5U-25-Pino'!I:I,'FPGA-SC-02033-2-0-ECP5U-25-Pino'!C:C,"") -> 3 | D32: =COUNTIF(K:K,A32) -> 0 | E32: =COUNTIF(K:K,H32) -> 0 | F32: =_xlfn.XLOOKUP(G32,'FPGA-SC-02033-2-0-ECP5U-25-Pino'!I:I,'FPGA-SC-02033-2-0-ECP5U-25-Pino'!C:C,"") -> 6 | G32: 58 | H32: N2 | I32: =D32+E32 -> 0
A33: R18 | B33: 59 | C33: =_xlfn.XLOOKUP(B33,'FPGA-SC-02033-2-0-ECP5U-25-Pino'!I:I,'FPGA-SC-02033-2-0-ECP5U-25-Pino'!C:C,"") -> 3 | D33: =COUNTIF(K:K,A33) -> 0 | E33: =COUNTIF(K:K,H33) -> 0 | F33: =_xlfn.XLOOKUP(G33,'FPGA-SC-02033-2-0-ECP5U-25-Pino'!I:I,'FPGA-SC-02033-2-0-ECP5U-25-Pino'!C:C,"") -> 6 | G33: 60 | H33: N3 | I33: =D33+E33 -> 0
A34: R17 | B34: 61 | C34: =_xlfn.XLOOKUP(B34,'FPGA-SC-02033-2-0-ECP5U-25-Pino'!I:I,'FPGA-SC-02033-2-0-ECP5U-25-Pino'!C:C,"") -> 3 | D34: =COUNTIF(K:K,A34) -> 0 | E34: =COUNTIF(K:K,H34) -> 0 | F34: =_xlfn.XLOOKUP(G34,'FPGA-SC-02033-2-0-ECP5U-25-Pino'!I:I,'FPGA-SC-02033-2-0-ECP5U-25-Pino'!C:C,"") -> 8 | G34: 62 | H34: T2 | I34: =D34+E34 -> 0
A35: P17 | B35: 63 | C35: =_xlfn.XLOOKUP(B35,'FPGA-SC-02033-2-0-ECP5U-25-Pino'!I:I,'FPGA-SC-02033-2-0-ECP5U-25-Pino'!C:C,"") -> 3 | D35: =COUNTIF(K:K,A35) -> 0 | E35: =COUNTIF(K:K,H35) -> 0 | F35: =_xlfn.XLOOKUP(G35,'FPGA-SC-02033-2-0-ECP5U-25-Pino'!I:I,'FPGA-SC-02033-2-0-ECP5U-25-Pino'!C:C,"") -> 6 | G35: 64 | H35: M3 | I35: =D35+E35 -> 0
... A103: GND | B103: 199 | C103: =_xlfn.XLOOKUP(B103,'FPGA-SC-02033-2-0-ECP5U-25-Pino'!I:I,'FPGA-SC-02033-2-0-ECP5U-25-Pino'!C:C,"") | D103: =COUNTIF(K:K,A103) -> 0 | E103: =COUNTIF(K:K,H103) -> 0 | F103: =_xlfn.XLOOKUP(G103,'FPGA-SC-02033-2-0-ECP5U-25-Pino'!I:I,'FPGA-SC-02033-2-0-ECP5U-25-Pino'!C:C,"") | G103: 200 | H103: GND | I103: =D103+E103 -> 0

Sheet FPGA-SC-02033-2-0-ECP5U-25-Pino
A1: PAD | B1: Pin/Ball Function | C1: Bank | D1: Dual Function | E1: Differential | F1: High Speed | G1: DQS | H1: CABGA381 | I1: SO-DIMM Pin
A2: 1 | B2: PL2A | C2: 7 | D2: - | E2: True_OF_PL2B | F2: TRUE | G2: LDQ8 | H2: A4 | I2: =_xlfn.XLOOKUP(H2,'SO-DIMM-i5'!A:A,'SO-DIMM-i5'!B:B,_xlfn.XLOOKUP(H2,'SO-DIMM-i5'!H:H,'SO-DIMM-i5'!G:G,""))
A3: 2 | B3: PL2B | C3: 7 | D3: - | E3: Comp_OF_PL2A | F3: TRUE | G3: LDQ8 | H3: A5 | I3: =_xlfn.XLOOKUP(H3,'SO-DIMM-i5'!A:A,'SO-DIMM-i5'!B:B,_xlfn.XLOOKUP(H3,'SO-DIMM-i5'!H:H,'SO-DIMM-i5'!G:G,""))
A4: 3 | B4: VSSIO7 | C4: - | D4: - | E4: - | F4: - | G4: - | H4: - | I4: =_xlfn.XLOOKUP(H4,'SO-DIMM-i5'!A:A,'SO-DIMM-i5'!B:B,_xlfn.XLOOKUP(H4,'SO-DIMM-i5'!H:H,'SO-DIMM-i5'!G:G,""))
A5: 4 | B5: PL2C | C5: 7 | D5: - | E5: True_OF_PL2D | F5: - | G5: LDQ8 | H5: B5 | I5: =_xlfn.XLOOKUP(H5,'SO-DIMM-i5'!A:A,'SO-DIMM-i5'!B:B,_xlfn.XLOOKUP(H5,'SO-DIMM-i5'!H:H,'SO-DIMM-i5'!G:G,""))
A6: 5 | B6: VCCIO7 | C6: - | D6: - | E6: - | F6: - | G6: - | H6: - | I6: =_xlfn.XLOOKUP(H6,'SO-DIMM-i5'!A:A,'SO-DIMM-i5'!B:B,_xlfn.XLOOKUP(H6,'SO-DIMM-i5'!H:H,'SO-DIMM-i5'!G:G,""))
A7: 6 | B7: PL2D | C7: 7 | D7: - | E7: Comp_OF_PL2C | F7: - | G7: LDQ8 | H7: C5 | I7: =_xlfn.XLOOKUP(H7,'SO-DIMM-i5'!A:A,'SO-DIMM-i5'!B:B,_xlfn.XLOOKUP(H7,'SO-DIMM-i5'!H:H,'SO-DIMM-i5'!G:G,""))
A8: 7 | B8: PL5A | C8: 7 | D8: - | E8: True_OF_PL5B | F8: TRUE | G8: LDQ8 | H8: C4 | I8: =_xlfn.XLOOKUP(H8,'SO-DIMM-i5'!A:A,'SO-DIMM-i5'!B:B,_xlfn.XLOOKUP(H8,'SO-DIMM-i5'!H:H,'SO-DIMM-i5'!G:G,"")) -> 131
A9: 8 | B9: VCCAUX | C9: - | D9: - | E9: - | F9: - | G9: - | H9: - | I9: =_xlfn.XLOOKUP(H9,'SO-DIMM-i5'!A:A,'SO-DIMM-i5'!B:B,_xlfn.XLOOKUP(H9,'SO-DIMM-i5'!H:H,'SO-DIMM-i5'!G:G,""))
A10: 9 | B10: PL5C | C10: 7 | D10: - | E10: True_OF_PL5D | F10: - | G10: LDQ8 | H10: A3 | I10: =_xlfn.XLOOKUP(H10,'SO-DIMM-i5'!A:A,'SO-DIMM-i5'!B:B,_xlfn.XLOOKUP(H10,'SO-DIMM-i5'!H:H,'SO-DIMM-i5'!G:G,"")) -> 139
A11: 10 | B11: PL5B | C11: 7 | D11: - | E11: Comp_OF_PL5A | F11: TRUE | G11: LDQ8 | H11: B4 | I11: =_xlfn.XLOOKUP(H11,'SO-DIMM-i5'!A:A,'SO-DIMM-i5'!B:B,_xlfn.XLOOKUP(H11,'SO-DIMM-i5'!H:H,'SO-DIMM-i5'!G:G,"")) -> 133
A12: 11 | B12: VSS | C12: - | D12: - | E12: - | F12: - | G12: - | H12: - | I12: =_xlfn.XLOOKUP(H12,'SO-DIMM-i5'!A:A,'SO-DIMM-i5'!B:B,_xlfn.XLOOKUP(H12,'SO-DIMM-i5'!H:H,'SO-DIMM-i5'!G:G,""))
A13: 12 | B13: PL5D | C13: 7 | D13: - | E13: Comp_OF_PL5C | F13: - | G13: LDQ8 | H13: B3 | I13: =_xlfn.XLOOKUP(H13,'SO-DIMM-i5'!A:A,'SO-DIMM-i5'!B:B,_xlfn.XLOOKUP(H13,'SO-DIMM-i5'!H:H,'SO-DIMM-i5'!G:G,"")) -> 152
A14: 13 | B14: PL8A | C14: 7 | D14: - | E14: True_OF_PL8B | F14: TRUE | G14: LDQS8 | H14: E4 | I14: =_xlfn.XLOOKUP(H14,'SO-DIMM-i5'!A:A,'SO-DIMM-i5'!B:B,_xlfn.XLOOKUP(H14,'SO-DIMM-i5'!H:H,'SO-DIMM-i5'!G:G,"")) -> 128
A15: 14 | B15: VCC | C15: - | D15: - | E15: - | F15: - | G15: - | H15: - | I15: =_xlfn.XLOOKUP(H15,'SO-DIMM-i5'!A:A,'SO-DIMM-i5'!B:B,_xlfn.XLOOKUP(H15,'SO-DIMM-i5'!H:H,'SO-DIMM-i5'!G:G,""))
A16: 15 | B16: PL8C | C16: 7 | D16: - | E16: True_OF_PL8D | F16: - | G16: LDQ8 | H16: C3 | I16: =_xlfn.XLOOKUP(H16,'SO-DIMM-i5'!A:A,'SO-DIMM-i5'!B:B,_xlfn.XLOOKUP(H16,'SO-DIMM-i5'!H:H,'SO-DIMM-i5'!G:G,"")) -> 135
A17: 16 | B17: PL8B | C17: 7 | D17: - | E17: Comp_OF_PL8A | F17: TRUE | G17: LDQSN8 | H17: D5 | I17: =_xlfn.XLOOKUP(H17,'SO-DIMM-i5'!A:A,'SO-DIMM-i5'!B:B,_xlfn.XLOOKUP(H17,'SO-DIMM-i5'!H:H,'SO-DIMM-i5'!G:G,""))
A18: 17 | B18: VSS | C18: - | D18: - | E18: - | F18: - | G18: - | H18: - | I18: =_xlfn.XLOOKUP(H18,'SO-DIMM-i5'!A:A,'SO-DIMM-i5'!B:B,_xlfn.XLOOKUP(H18,'SO-DIMM-i5'!H:H,'SO-DIMM-i5'!G:G,""))
A19: 18 | B19: PL8D | C19: 7 | D19: - | E19: Comp_OF_PL8C | F19: - | G19: LDQ8 | H19: D3 | I19: =_xlfn.XLOOKUP(H19,'SO-DIMM-i5'!A:A,'SO-DIMM-i5'!B:B,_xlfn.XLOOKUP(H19,'SO-DIMM-i5'!H:H,'SO-DIMM-i5'!G:G,"")) -> 129
A20: 19 | B20: PL11A | C20: 7 | D20: - | E20: True_OF_PL11B | F20: TRUE | G20: LDQ8 | H20: F4 | I20: =_xlfn.XLOOKUP(H20,'SO-DIMM-i5'!A:A,'SO-DIMM-i5'!B:B,_xlfn.XLOOKUP(H20,'SO-DIMM-i5'!H:H,'SO-DIMM-i5'!G:G,"")) -> 126
A21: 20 | B21: VSSIO7 | C21: - | D21: - | E21: - | F21: - | G21: - | H21: - | I21: =_xlfn.XLOOKUP(H21,'SO-DIMM-i5'!A:A,'SO-DIMM-i5'!B:B,_xlfn.XLOOKUP(H21,'SO-DIMM-i5'!H:H,'SO-DIMM-i5'!G:G,""))
A22: 21 | B22: PL11C | C22: 7 | D22: - | E22: True_OF_PL11D | F22: - | G22: LDQ8 | H22: E5 | I22: =_xlfn.XLOOKUP(H22,'SO-DIMM-i5'!A:A,'SO-DIMM-i5'!B:B,_xlfn.XLOOKUP(H22,'SO-DIMM-i5'!H:H,'SO-DIMM-i5'!G:G,"")) -> 124
A23: 22 | B23: PL11B | C23: 7 | D23: - | E23: Comp_OF_PL11A | F23: TRUE | G23: LDQ8 | H23: E3 | I23: =_xlfn.XLOOKUP(H23,'SO-DIMM-i5'!A:A,'SO-DIMM-i5'!B:B,_xlfn.XLOOKUP(H23,'SO-DIMM-i5'!H:H,'SO-DIMM-i5'!G:G,"")) -> 137
A24: 23 | B24: VCCIO7 | C24: - | D24: - | E24: - | F24: - | G24: - | H24: - | I24: =_xlfn.XLOOKUP(H24,'SO-DIMM-i5'!A:A,'SO-DIMM-i5'!B:B,_xlfn.XLOOKUP(H24,'SO-DIMM-i5'!H:H,'SO-DIMM-i5'!G:G,""))
A25: 24 | B25: PL11D | C25: 7 | D25: - | E25: Comp_OF_PL11C | F25: - | G25: LDQ8 | H25: F5 | I25: =_xlfn.XLOOKUP(H25,'SO-DIMM-i5'!A:A,'SO-DIMM-i5'!B:B,_xlfn.XLOOKUP(H25,'SO-DIMM-i5'!H:H,'SO-DIMM-i5'!G:G,"")) -> 120
A26: 25 | B26: PL14A | C26: 7 | D26: - | E26: True_OF_PL14B | F26: TRUE | G26: LDQ20 | H26: A2 | I26: =_xlfn.XLOOKUP(H26,'SO-DIMM-i5'!A:A,'SO-DIMM-i5'!B:B,_xlfn.XLOOKUP(H26,'SO-DIMM-i5'!H:H,'SO-DIMM-i5'!G:G,"")) -> 154
A27: 26 | B27: VSSIO7 | C27: - | D27: - | E27: - | F27: - | G27: - | H27: - | I27: =_xlfn.XLOOKUP(H27,'SO-DIMM-i5'!A:A,'SO-DIMM-i5'!B:B,_xlfn.XLOOKUP(H27,'SO-DIMM-i5'!H:H,'SO-DIMM-i5'!G:G,""))
A28: 27 | B28: PL14C | C28: 7 | D28: VREF1_7 | E28: True_OF_PL14D | F28: - | G28: LDQ20 | H28: B2 | I28: =_xlfn.XLOOKUP(H28,'SO-DIMM-i5'!A:A,'SO-DIMM-i5'!B:B,_xlfn.XLOOKUP(H28,'SO-DIMM-i5'!H:H,'SO-DIMM-i5'!G:G,"")) -> 156
A29: 28 | B29: PL14B | C29: 7 | D29: - | E29: Comp_OF_PL14A | F29: TRUE | G29: LDQ20 | H29: B1 | I29: =_xlfn.XLOOKUP(H29,'SO-DIMM-i5'!A:A,'SO-DIMM-i5'!B:B,_xlfn.XLOOKUP(H29,'SO-DIMM-i5'!H:H,'SO-DIMM-i5'!G:G,"")) -> 143
A30: 29 | B30: VCCIO7 | C30: - | D30: - | E30: - | F30: - | G30: - | H30: - | I30: =_xlfn.XLOOKUP(H30,'SO-DIMM-i5'!A:A,'SO-DIMM-i5'!B:B,_xlfn.XLOOKUP(H30,'SO-DIMM-i5'!H:H,'SO-DIMM-i5'!G:G,""))
A31: 30 | B31: PL14D | C31: 7 | D31: - | E31: Comp_OF_PL14C | F31: - | G31: LDQ20 | H31: C2 | I31: =_xlfn.XLOOKUP(H31,'SO-DIMM-i5'!A:A,'SO-DIMM-i5'!B:B,_xlfn.XLOOKUP(H31,'SO-DIMM-i5'!H:H,'SO-DIMM-i5'!G:G,"")) -> 141
A32: 31 | B32: PL17A | C32: 7 | D32: - | E32: True_OF_PL17B | F32: TRUE | G32: LDQ20 | H32: C1 | I32: =_xlfn.XLOOKUP(H32,'SO-DIMM-i5'!A:A,'SO-DIMM-i5'!B:B,_xlfn.XLOOKUP(H32,'SO-DIMM-i5'!H:H,'SO-DIMM-i5'!G:G,"")) -> 145
A33: 32 | B33: VCCAUX | C33: - | D33: - | E33: - | F33: - | G33: - | H33: - | I33: =_xlfn.XLOOKUP(H33,'SO-DIMM-i5'!A:A,'SO-DIMM-i5'!B:B,_xlfn.XLOOKUP(H33,'SO-DIMM-i5'!H:H,'SO-DIMM-i5'!G:G,""))
A34: 33 | B34: PL17C | C34: 7 | D34: - | E34: True_OF_PL17D | F34: - | G34: LDQ20 | H34: D2 | I34: =_xlfn.XLOOKUP(H34,'SO-DIMM-i5'!A:A,'SO-DIMM-i5'!B:B,_xlfn.XLOOKUP(H34,'SO-DIMM-i5'!H:H,'SO-DIMM-i5'!G:G,"")) -> 147
A35: 34 | B35: PL17B | C35: 7 | D35: - | E35: Comp_OF_PL17A | F35: TRUE | G35: LDQ20 | H35: D1 | I35: =_xlfn.XLOOKUP(H35,'SO-DIMM-i5'!A:A,'SO-DIMM-i5'!B:B,_xlfn.XLOOKUP(H35,'SO-DIMM-i5'!H:H,'SO-DIMM-i5'!G:G,"")) -> 149
A36: 35 | B36: VSS | C36: - | D36: - | E36: - | F36: - | G36: - | H36: - | I36: =_xlfn.XLOOKUP(H36,'SO-DIMM-i5'!A:A,'SO-DIMM-i5'!B:B,_xlfn.XLOOKUP(H36,'SO-DIMM-i5'!H:H,'SO-DIMM-i5'!G:G,""))
A37: 36 | B37: PL17D | C37: 7 | D37: - | E37: Comp_OF_PL17C | F37: - | G37: LDQ20 | H37: E1 | I37: =_xlfn.XLOOKUP(H37,'SO-DIMM-i5'!A:A,'SO-DIMM-i5'!B:B,_xlfn.XLOOKUP(H37,'SO-DIMM-i5'!H:H,'SO-DIMM-i5'!G:G,"")) -> 153
A38: 37 | B38: PL20A | C38: 7 | D38: GR_PCLK7_1 | E38: True_OF_PL20B | F38: TRUE | G38: LDQS20 | H38: H4 | I38: =_xlfn.XLOOKUP(H38,'SO-DIMM-i5'!A:A,'SO-DIMM-i5'!B:B,_xlfn.XLOOKUP(H38,'SO-DIMM-i5'!H:H,'SO-DIMM-i5'!G:G,"")) -> 138 | K38: =I38 -> 138
A39: 38 | B39: VCC | C39: - | D39: - | E39: - | F39: - | G39: - | H39: - | I39: =_xlfn.XLOOKUP(H39,'SO-DIMM-i5'!A:A,'SO-DIMM-i5'!B:B,_xlfn.XLOOKUP(H39,'SO-DIMM-i5'!H:H,'SO-DIMM-i5'!G:G,""))
A40: 39 | B40: PL20C | C40: 7 | D40: GR_PCLK7_0 | E40: True_OF_PL20D | F40: - | G40: LDQ20 | H40: H5 | I40: =_xlfn.XLOOKUP(H40,'SO-DIMM-i5'!A:A,'SO-DIMM-i5'!B:B,_xlfn.XLOOKUP(H40,'SO-DIMM-i5'!H:H,'SO-DIMM-i5'!G:G,"")) -> 140 | K40: =I40 -> 140
...

Sheet SO-DIMM-i9
A1: Function | B1: Top-Pin | C1: Bank | D1: CLK | E1: CLK | F1: Bank | G1: Bot-Pin | H1: Function | K1: Clocks
A2: GND | B2: 1 | C2: =_xlfn.XLOOKUP(B2,'FPGA-SC-02033-2-0-ECP5U-25-Pino'!I:I,'FPGA-SC-02033-2-0-ECP5U-25-Pino'!C:C,"") | D2: =COUNTIF(K:K,A2) -> 0 | E2: =COUNTIF(K:K,H2) -> 0 | F2: =_xlfn.XLOOKUP(G2,'FPGA-SC-02033-2-0-ECP5U-25-Pino'!I:I,'FPGA-SC-02033-2-0-ECP5U-25-Pino'!C:C,"") | G2: 2 | H2: 5V | I2: =D2+E2 -> 0 | K2: H4
A3: GND | B3: 3 | C3: =_xlfn.XLOOKUP(B3,'FPGA-SC-02033-2-0-ECP5U-25-Pino'!I:I,'FPGA-SC-02033-2-0-ECP5U-25-Pino'!C:C,"") | D3: =COUNTIF(K:K,A3) -> 0 | E3: =COUNTIF(K:K,H3) -> 0 | F3: =_xlfn.XLOOKUP(G3,'FPGA-SC-02033-2-0-ECP5U-25-Pino'!I:I,'FPGA-SC-02033-2-0-ECP5U-25-Pino'!C:C,"") | G3: 4 | H3: 5V | I3: =D3+E3 -> 0 | K3: H5
A4: GND | B4: 5 | C4: =_xlfn.XLOOKUP(B4,'FPGA-SC-02033-2-0-ECP5U-25-Pino'!I:I,'FPGA-SC-02033-2-0-ECP5U-25-Pino'!C:C,"") | D4: =COUNTIF(K:K,A4) -> 0 | E4: =COUNTIF(K:K,H4) -> 0 | F4: =_xlfn.XLOOKUP(G4,'FPGA-SC-02033-2-0-ECP5U-25-Pino'!I:I,'FPGA-SC-02033-2-0-ECP5U-25-Pino'!C:C,"") | G4: 6 | H4: 5V | I4: =D4+E4 -> 0 | K4: G3
A5: GND | B5: 7 | C5: =_xlfn.XLOOKUP(B5,'FPGA-SC-02033-2-0-ECP5U-25-Pino'!I:I,'FPGA-SC-02033-2-0-ECP5U-25-Pino'!C:C,"") | D5: =COUNTIF(K:K,A5) -> 0 | E5: =COUNTIF(K:K,H5) -> 0 | F5: =_xlfn.XLOOKUP(G5,'FPGA-SC-02033-2-0-ECP5U-25-Pino'!I:I,'FPGA-SC-02033-2-0-ECP5U-25-Pino'!C:C,"") | G5: 8 | H5: 5V | I5: =D5+E5 -> 0 | K5: F2
A6: GND | B6: 9 | C6: =_xlfn.XLOOKUP(B6,'FPGA-SC-02033-2-0-ECP5U-25-Pino'!I:I,'FPGA-SC-02033-2-0-ECP5U-25-Pino'!C:C,"") | D6: =COUNTIF(K:K,A6) -> 0 | E6: =COUNTIF(K:K,H6) -> 0 | F6: =_xlfn.XLOOKUP(G6,'FPGA-SC-02033-2-0-ECP5U-25-Pino'!I:I,'FPGA-SC-02033-2-0-ECP5U-25-Pino'!C:C,"") | G6: 10 | H6: 5V | I6: =D6+E6 -> 0 | K6: F3
A7: GND | B7: 11 | C7: =_xlfn.XLOOKUP(B7,'FPGA-SC-02033-2-0-ECP5U-25-Pino'!I:I,'FPGA-SC-02033-2-0-ECP5U-25-Pino'!C:C,"") | D7: =COUNTIF(K:K,A7) -> 0 | E7: =COUNTIF(K:K,H7) -> 0 | F7: =_xlfn.XLOOKUP(G7,'FPGA-SC-02033-2-0-ECP5U-25-Pino'!I:I,'FPGA-SC-02033-2-0-ECP5U-25-Pino'!C:C,"") | G7: 12 | H7: 5V | I7: =D7+E7 -> 0 | K7: E2
A8: NC | B8: 13 | C8: =_xlfn.XLOOKUP(B8,'FPGA-SC-02033-2-0-ECP5U-25-Pino'!I:I,'FPGA-SC-02033-2-0-ECP5U-25-Pino'!C:C,"") | D8: =COUNTIF(K:K,A8) -> 0 | E8: =COUNTIF(K:K,H8) -> 0 | F8: =_xlfn.XLOOKUP(G8,'FPGA-SC-02033-2-0-ECP5U-25-Pino'!I:I,'FPGA-SC-02033-2-0-ECP5U-25-Pino'!C:C,"") | G8: 14 | H8: NC | I8: =D8+E8 -> 0 | K8: F1
A9: ETH1_1P | B9: 15 | C9: =_xlfn.XLOOKUP(B9,'FPGA-SC-02033-2-0-ECP5U-25-Pino'!I:I,'FPGA-SC-02033-2-0-ECP5U-25-Pino'!C:C,"") | D9: =COUNTIF(K:K,A9) -> 0 | E9: =COUNTIF(K:K,H9) -> 0 | F9: =_xlfn.XLOOKUP(G9,'FPGA-SC-02033-2-0-ECP5U-25-Pino'!I:I,'FPGA-SC-02033-2-0-ECP5U-25-Pino'!C:C,"") | G9: 16 | H9: ETH2_1P | I9: =D9+E9 -> 0 | K9: J4
A10: ETH1_1N | B10: 17 | C10: =_xlfn.XLOOKUP(B10,'FPGA-SC-02033-2-0-ECP5U-25-Pino'!I:I,'FPGA-SC-02033-2-0-ECP5U-25-Pino'!C:C,"") | D10: =COUNTIF(K:K,A10) -> 0 | E10: =COUNTIF(K:K,H10) -> 0 | F10: =_xlfn.XLOOKUP(G10,'FPGA-SC-02033-2-0-ECP5U-25-Pino'!I:I,'FPGA-SC-02033-2-0-ECP5U-25-Pino'!C:C,"") | G10: 18 | H10: ETH2_1N | I10: =D10+E10 -> 0 | K10: L18
A11: NC | B11: 19 | C11: =_xlfn.XLOOKUP(B11,'FPGA-SC-02033-2-0-ECP5U-25-Pino'!I:I,'FPGA-SC-02033-2-0-ECP5U-25-Pino'!C:C,"") | D11: =COUNTIF(K:K,A11) -> 0 | E11: =COUNTIF(K:K,H11) -> 0 | F11: =_xlfn.XLOOKUP(G11,'FPGA-SC-02033-2-0-ECP5U-25-Pino'!I:I,'FPGA-SC-02033-2-0-ECP5U-25-Pino'!C:C,"") | G11: 20 | H11: NC | I11: =D11+E11 -> 0 | K11: L20
A12: ETH1_2N | B12: 21 | C12: =_xlfn.XLOOKUP(B12,'FPGA-SC-02033-2-0-ECP5U-25-Pino'!I:I,'FPGA-SC-02033-2-0-ECP5U-25-Pino'!C:C,"") | D12: =COUNTIF(K:K,A12) -> 0 | E12: =COUNTIF(K:K,H12) -> 0 | F12: =_xlfn.XLOOKUP(G12,'FPGA-SC-02033-2-0-ECP5U-25-Pino'!I:I,'FPGA-SC-02033-2-0-ECP5U-25-Pino'!C:C,"") | G12: 22 | H12: ETH2_2N | I12: =D12+E12 -> 0 | K12: K20
A13: ETH1_2P | B13: 23 | C13: =_xlfn.XLOOKUP(B13,'FPGA-SC-02033-2-0-ECP5U-25-Pino'!I:I,'FPGA-SC-02033-2-0-ECP5U-25-Pino'!C:C,"") | D13: =COUNTIF(K:K,A13) -> 0 | E13: =COUNTIF(K:K,H13) -> 0 | F13: =_xlfn.XLOOKUP(G13,'FPGA-SC-02033-2-0-ECP5U-25-Pino'!I:I,'FPGA-SC-02033-2-0-ECP5U-25-Pino'!C:C,"") | G13: 24 | H13: ETH2_2P | I13: =D13+E13 -> 0 | K13: K19
... A17: NC | B17: 31 | C17: =_xlfn.XLOOKUP(B17,'FPGA-SC-02033-2-0-ECP5U-25-Pino'!I:I,'FPGA-SC-02033-2-0-ECP5U-25-Pino'!C:C,"") | D17: =COUNTIF(K:K,A17) -> 0 | E17: =COUNTIF(K:K,H17) -> 0 | F17: =_xlfn.XLOOKUP(G17,'FPGA-SC-02033-2-0-ECP5U-25-Pino'!I:I,'FPGA-SC-02033-2-0-ECP5U-25-Pino'!C:C,"") | G17: 32 | H17: NC | I17: =D17+E17 -> 0 | K17: G19
A18: ETH1_4N | B18: 33 | C18: =_xlfn.XLOOKUP(B18,'FPGA-SC-02033-2-0-ECP5U-25-Pino'!I:I,'FPGA-SC-02033-2-0-ECP5U-25-Pino'!C:C,"") | D18: =COUNTIF(K:K,A18) -> 0 | E18: =COUNTIF(K:K,H18) -> 0 | F18: =_xlfn.XLOOKUP(G18,'FPGA-SC-02033-2-0-ECP5U-25-Pino'!I:I,'FPGA-SC-02033-2-0-ECP5U-25-Pino'!C:C,"") | G18: 34 | H18: ETH2_4N | I18: =D18+E18 -> 0
A19: ETH1_4P | B19: 35 | C19: =_xlfn.XLOOKUP(B19,'FPGA-SC-02033-2-0-ECP5U-25-Pino'!I:I,'FPGA-SC-02033-2-0-ECP5U-25-Pino'!C:C,"") | D19: =COUNTIF(K:K,A19) -> 0 | E19: =COUNTIF(K:K,H19) -> 0 | F19: =_xlfn.XLOOKUP(G19,'FPGA-SC-02033-2-0-ECP5U-25-Pino'!I:I,'FPGA-SC-02033-2-0-ECP5U-25-Pino'!C:C,"") | G19: 36 | H19: ETH2_4P | I19: =D19+E19 -> 0
A20: NC | B20: 37 | C20: =_xlfn.XLOOKUP(B20,'FPGA-SC-02033-2-0-ECP5U-25-Pino'!I:I,'FPGA-SC-02033-2-0-ECP5U-25-Pino'!C:C,"") | D20: =COUNTIF(K:K,A20) -> 0 | E20: =COUNTIF(K:K,H20) -> 0 | F20: =_xlfn.XLOOKUP(G20,'FPGA-SC-02033-2-0-ECP5U-25-Pino'!I:I,'FPGA-SC-02033-2-0-ECP5U-25-Pino'!C:C,"") | G20: 38 | H20: NC | I20: =D20+E20 -> 0
A21: GND | B21: 39 | C21: =_xlfn.XLOOKUP(B21,'FPGA-SC-02033-2-0-ECP5U-25-Pino'!I:I,'FPGA-SC-02033-2-0-ECP5U-25-Pino'!C:C,"") | D21: =COUNTIF(K:K,A21) -> 0 | E21: =COUNTIF(K:K,H21) -> 0 | F21: =_xlfn.XLOOKUP(G21,'FPGA-SC-02033-2-0-ECP5U-25-Pino'!I:I,'FPGA-SC-02033-2-0-ECP5U-25-Pino'!C:C,"") | G21: 40 | H21: GND | I21: =D21+E21 -> 0
I22: =D22+E22 -> 0
I23: =D23+E23 -> 0
A24: L2 | B24: 41 | C24: =_xlfn.XLOOKUP(B24,'FPGA-SC-02033-2-0-ECP5U-25-Pino'!I:I,'FPGA-SC-02033-2-0-ECP5U-25-Pino'!C:C,"") -> 3 | D24: =COUNTIF(K:K,A24) -> 0 | E24: =COUNTIF(K:K,H24) -> 0 | F24: =_xlfn.XLOOKUP(G24,'FPGA-SC-02033-2-0-ECP5U-25-Pino'!I:I,'FPGA-SC-02033-2-0-ECP5U-25-Pino'!C:C,"") -> 8 | G24: 42 | H24: R1 | I24: =D24+E24 -> 0
A25: NC | B25: 43 | C25: =_xlfn.XLOOKUP(B25,'FPGA-SC-02033-2-0-ECP5U-25-Pino'!I:I,'FPGA-SC-02033-2-0-ECP5U-25-Pino'!C:C,"") | D25: =COUNTIF(K:K,A25) -> 0 | E25: =COUNTIF(K:K,H25) -> 0 | F25: =_xlfn.XLOOKUP(G25,'FPGA-SC-02033-2-0-ECP5U-25-Pino'!I:I,'FPGA-SC-02033-2-0-ECP5U-25-Pino'!C:C,"") -> 8 | G25: 44 | H25: T1 | I25: =D25+E25 -> 0
A26: NC | B26: 45 | C26: =_xlfn.XLOOKUP(B26,'FPGA-SC-02033-2-0-ECP5U-25-Pino'!I:I,'FPGA-SC-02033-2-0-ECP5U-25-Pino'!C:C,"") | D26: =COUNTIF(K:K,A26) -> 0 | E26: =COUNTIF(K:K,H26) -> 0 | F26: =_xlfn.XLOOKUP(G26,'FPGA-SC-02033-2-0-ECP5U-25-Pino'!I:I,'FPGA-SC-02033-2-0-ECP5U-25-Pino'!C:C,"") -> 8 | G26: 46 | H26: U1 | I26: =D26+E26 -> 0
A27: NC | B27: 47 | C27: =_xlfn.XLOOKUP(B27,'FPGA-SC-02033-2-0-ECP5U-25-Pino'!I:I,'FPGA-SC-02033-2-0-ECP5U-25-Pino'!C:C,"") | D27: =COUNTIF(K:K,A27) -> 0 | E27: =COUNTIF(K:K,H27) -> 0 | F27: =_xlfn.XLOOKUP(G27,'FPGA-SC-02033-2-0-ECP5U-25-Pino'!I:I,'FPGA-SC-02033-2-0-ECP5U-25-Pino'!C:C,"") -> 8 | G27: 48 | H27: Y2 | I27: =D27+E27 -> 0
A28: K18 | B28: 49 | C28: =_xlfn.XLOOKUP(B28,'FPGA-SC-02033-2-0-ECP5U-25-Pino'!I:I,'FPGA-SC-02033-2-0-ECP5U-25-Pino'!C:C,"") -> 2 | D28: =COUNTIF(K:K,A28) -> 0 | E28: =COUNTIF(K:K,H28) -> 0 | F28: =_xlfn.XLOOKUP(G28,'FPGA-SC-02033-2-0-ECP5U-25-Pino'!I:I,'FPGA-SC-02033-2-0-ECP5U-25-Pino'!C:C,"") -> 8 | G28: 50 | H28: W1 | I28: =D28+E28 -> 0
A29: C18 | B29: 51 | C29: =_xlfn.XLOOKUP(B29,'FPGA-SC-02033-2-0-ECP5U-25-Pino'!I:I,'FPGA-SC-02033-2-0-ECP5U-25-Pino'!C:C,"") -> 2 | D29: =COUNTIF(K:K,A29) -> 0 | E29: =COUNTIF(K:K,H29) -> 0 | F29: =_xlfn.XLOOKUP(G29,'FPGA-SC-02033-2-0-ECP5U-25-Pino'!I:I,'FPGA-SC-02033-2-0-ECP5U-25-Pino'!C:C,"") -> 8 | G29: 52 | H29: V1 | I29: =D29+E29 -> 0
A30: NC | B30: 53 | C30: =_xlfn.XLOOKUP(B30,'FPGA-SC-02033-2-0-ECP5U-25-Pino'!I:I,'FPGA-SC-02033-2-0-ECP5U-25-Pino'!C:C,"") | D30: =COUNTIF(K:K,A30) -> 0 | E30: =COUNTIF(K:K,H30) -> 0 | F30: =_xlfn.XLOOKUP(G30,'FPGA-SC-02033-2-0-ECP5U-25-Pino'!I:I,'FPGA-SC-02033-2-0-ECP5U-25-Pino'!C:C,"") -> 6 | G30: 54 | H30: M1 | I30: =D30+E30 -> 0
A31: GND | B31: 55 | C31: =_xlfn.XLOOKUP(B31,'FPGA-SC-02033-2-0-ECP5U-25-Pino'!I:I,'FPGA-SC-02033-2-0-ECP5U-25-Pino'!C:C,"") | D31: =COUNTIF(K:K,A31) -> 0 | E31: =COUNTIF(K:K,H31) -> 0 | F31: =_xlfn.XLOOKUP(G31,'FPGA-SC-02033-2-0-ECP5U-25-Pino'!I:I,'FPGA-SC-02033-2-0-ECP5U-25-Pino'!C:C,"") | G31: 56 | H31: GND | I31: =D31+E31 -> 0
A32: T18 | B32: 57 | C32: =_xlfn.XLOOKUP(B32,'FPGA-SC-02033-2-0-ECP5U-25-Pino'!I:I,'FPGA-SC-02033-2-0-ECP5U-25-Pino'!C:C,"") -> 3 | D32: =COUNTIF(K:K,A32) -> 0 | E32: =COUNTIF(K:K,H32) -> 0 | F32: =_xlfn.XLOOKUP(G32,'FPGA-SC-02033-2-0-ECP5U-25-Pino'!I:I,'FPGA-SC-02033-2-0-ECP5U-25-Pino'!C:C,"") -> 6 | G32: 58 | H32: N2 | I32: =D32+E32 -> 0
A33: R18 | B33: 59 | C33: =_xlfn.XLOOKUP(B33,'FPGA-SC-02033-2-0-ECP5U-25-Pino'!I:I,'FPGA-SC-02033-2-0-ECP5U-25-Pino'!C:C,"") -> 3 | D33: =COUNTIF(K:K,A33) -> 0 | E33: =COUNTIF(K:K,H33) -> 0 | F33: =_xlfn.XLOOKUP(G33,'FPGA-SC-02033-2-0-ECP5U-25-Pino'!I:I,'FPGA-SC-02033-2-0-ECP5U-25-Pino'!C:C,"") -> 6 | G33: 60 | H33: N3 | I33: =D33+E33 -> 0
A34: R17 | B34: 61 | C34: =_xlfn.XLOOKUP(B34,'FPGA-SC-02033-2-0-ECP5U-25-Pino'!I:I,'FPGA-SC-02033-2-0-ECP5U-25-Pino'!C:C,"") -> 3 | D34: =COUNTIF(K:K,A34) -> 0 | E34: =COUNTIF(K:K,H34) -> 0 | F34: =_xlfn.XLOOKUP(G34,'FPGA-SC-02033-2-0-ECP5U-25-Pino'!I:I,'FPGA-SC-02033-2-0-ECP5U-25-Pino'!C:C,"") -> 8 | G34: 62 | H34: T2 | I34: =D34+E34 -> 0
A35: P17 | B35: 63 | C35: =_xlfn.XLOOKUP(B35,'FPGA-SC-02033-2-0-ECP5U-25-Pino'!I:I,'FPGA-SC-02033-2-0-ECP5U-25-Pino'!C:C,"") -> 3 | D35: =COUNTIF(K:K,A35) -> 0 | E35: =COUNTIF(K:K,H35) -> 0 | F35: =_xlfn.XLOOKUP(G35,'FPGA-SC-02033-2-0-ECP5U-25-Pino'!I:I,'FPGA-SC-02033-2-0-ECP5U-25-Pino'!C:C,"") -> 6 | G35: 64 | H35: M3 | I35: =D35+E35 -> 0
... A103: GND | B103: 199 | C103: =_xlfn.XLOOKUP(B103,'FPGA-SC-02033-2-0-ECP5U-25-Pino'!I:I,'FPGA-SC-02033-2-0-ECP5U-25-Pino'!C:C,"") | D103: =COUNTIF(K:K,A103) -> 0 | E103: =COUNTIF(K:K,H103) -> 0 | F103: =_xlfn.XLOOKUP(G103,'FPGA-SC-02033-2-0-ECP5U-25-Pino'!I:I,'FPGA-SC-02033-2-0-ECP5U-25-Pino'!C:C,"") | G103: 200 | H103: GND | I103: =D103+E103 -> 0

Sheet FPGA-SC-02034-3-0-ECP5U-45-Pino
A1: # Pin Out For ECP5U-45
A2: # Revision 2.0. Added caBGA256 Package
A3: # Revised Mar. 19, 2018
A4: # Revision 3.0. Added TQFP144 Package
A5: # Revised Sep 17, 2021
A9: PAD | B9: Pin/Ball Function | C9: Bank | D9: Dual Function | E9: Differential | F9: High Speed | G9: DQS | H9: CABGA381 | I9: SO-DIMM Pin
A10: 1 | B10: NC | C10: - | D10: - | E10: - | F10: - | G10: - | H10: -
A11: 2 | B11: NC | C11: - | D11: - | E11: - | F11: - | G11: - | H11: -
A12: 3 | B12: NC | C12: - | D12: - | E12: - | F12: - | G12: - | H12: -
A13: 4 | B13: NC | C13: - | D13: - | E13: - | F13: - | G13: - | H13: -
A14: 5 | B14: NC | C14: - | D14: - | E14: - | F14: - | G14: - | H14: -
A15: 6 | B15: PL11A | C15: 7 | D15: ULC_GPLL0T_IN | E15: True_OF_PL11B | F15: TRUE | G15: LDQ17 | H15: A4 | I15: =_xlfn.XLOOKUP(H15,'SO-DIMM-i9'!A:A,'SO-DIMM-i9'!B:B,_xlfn.XLOOKUP(H15,'SO-DIMM-i9'!H:H,'SO-DIMM-i9'!G:G,""))
A16: 7 | B16: PL11B | C16: 7 | D16: ULC_GPLL0C_IN | E16: Comp_OF_PL11A | F16: TRUE | G16: LDQ17 | H16: A5 | I16: =_xlfn.XLOOKUP(H16,'SO-DIMM-i9'!A:A,'SO-DIMM-i9'!B:B,_xlfn.XLOOKUP(H16,'SO-DIMM-i9'!H:H,'SO-DIMM-i9'!G:G,""))
A17: 8 | B17: VSSIO7 | C17: - | D17: - | E17: - | F17: - | G17: - | H17: -
A18: 9 | B18: PL11C | C18: 7 | D18: - | E18: True_OF_PL11D | F18: - | G18: LDQ17 | H18: B5 | I18: =_xlfn.XLOOKUP(H18,'SO-DIMM-i9'!A:A,'SO-DIMM-i9'!B:B,_xlfn.XLOOKUP(H18,'SO-DIMM-i9'!H:H,'SO-DIMM-i9'!G:G,""))
A19: 10 | B19: VCCIO7 | C19: - | D19: - | E19: - | F19: - | G19: - | H19: -
A20: 11 | B20: PL11D | C20: 7 | D20: - | E20: Comp_OF_PL11C | F20: - | G20: LDQ17 | H20: C5 | I20: =_xlfn.XLOOKUP(H20,'SO-DIMM-i9'!A:A,'SO-DIMM-i9'!B:B,_xlfn.XLOOKUP(H20,'SO-DIMM-i9'!H:H,'SO-DIMM-i9'!G:G,""))
A21: 12 | B21: PL14A | C21: 7 | D21: - | E21: True_OF_PL14B | F21: TRUE | G21: LDQ17 | H21: C4 | I21: =_xlfn.XLOOKUP(H21,'SO-DIMM-i9'!A:A,'SO-DIMM-i9'!B:B,_xlfn.XLOOKUP(H21,'SO-DIMM-i9'!H:H,'SO-DIMM-i9'!G:G,"")) -> 131
A22: 13 | B22: VCCAUX | C22: - | D22: - | E22: - | F22: - | G22: - | H22: -
A23: 14 | B23: PL14C | C23: 7 | D23: - | E23: True_OF_PL14D | F23: - | G23: LDQ17 | H23: A3 | I23: =_xlfn.XLOOKUP(H23,'SO-DIMM-i9'!A:A,'SO-DIMM-i9'!B:B,_xlfn.XLOOKUP(H23,'SO-DIMM-i9'!H:H,'SO-DIMM-i9'!G:G,"")) -> 139
A24: 15 | B24: PL14B | C24: 7 | D24: - | E24: Comp_OF_PL14A | F24: TRUE | G24: LDQ17 | H24: B4 | I24: =_xlfn.XLOOKUP(H24,'SO-DIMM-i9'!A:A,'SO-DIMM-i9'!B:B,_xlfn.XLOOKUP(H24,'SO-DIMM-i9'!H:H,'SO-DIMM-i9'!G:G,"")) -> 133
A25: 16 | B25: VSS | C25: - | D25: - | E25: - | F25: - | G25: - | H25: -
A26: 17 | B26: PL14D | C26: 7 | D26: - | E26: Comp_OF_PL14C | F26: - | G26: LDQ17 | H26: B3 | I26: =_xlfn.XLOOKUP(H26,'SO-DIMM-i9'!A:A,'SO-DIMM-i9'!B:B,_xlfn.XLOOKUP(H26,'SO-DIMM-i9'!H:H,'SO-DIMM-i9'!G:G,"")) -> 152
A27: 18 | B27: PL17A | C27: 7 | D27: - | E27: True_OF_PL17B | F27: TRUE | G27: LDQS17 | H27: E4 | I27: =_xlfn.XLOOKUP(H27,'SO-DIMM-i9'!A:A,'SO-DIMM-i9'!B:B,_xlfn.XLOOKUP(H27,'SO-DIMM-i9'!H:H,'SO-DIMM-i9'!G:G,"")) -> 128
A28: 19 | B28: VCC | C28: - | D28: - | E28: - | F28: - | G28: - | H28: -
A29: 20 | B29: PL17C | C29: 7 | D29: - | E29: True_OF_PL17D | F29: - | G29: LDQ17 | H29: C3 | I29: =_xlfn.XLOOKUP(H29,'SO-DIMM-i9'!A:A,'SO-DIMM-i9'!B:B,_xlfn.XLOOKUP(H29,'SO-DIMM-i9'!H:H,'SO-DIMM-i9'!G:G,"")) -> 135
A30: 21 | B30: PL17B | C30: 7 | D30: - | E30: Comp_OF_PL17A | F30: TRUE | G30: LDQSN17 | H30: D5 | I30: =_xlfn.XLOOKUP(H30,'SO-DIMM-i9'!A:A,'SO-DIMM-i9'!B:B,_xlfn.XLOOKUP(H30,'SO-DIMM-i9'!H:H,'SO-DIMM-i9'!G:G,""))
A31: 22 | B31: VSS | C31: - | D31: - | E31: - | F31: - | G31: - | H31: -
A32: 23 | B32: PL17D | C32: 7 | D32: - | E32: Comp_OF_PL17C | F32: - | G32: LDQ17 | H32: D3 | I32: =_xlfn.XLOOKUP(H32,'SO-DIMM-i9'!A:A,'SO-DIMM-i9'!B:B,_xlfn.XLOOKUP(H32,'SO-DIMM-i9'!H:H,'SO-DIMM-i9'!G:G,"")) -> 129
A33: 24 | B33: PL20A | C33: 7 | D33: - | E33: True_OF_PL20B | F33: TRUE | G33: LDQ17 | H33: F4 | I33: =_xlfn.XLOOKUP(H33,'SO-DIMM-i9'!A:A,'SO-DIMM-i9'!B:B,_xlfn.XLOOKUP(H33,'SO-DIMM-i9'!H:H,'SO-DIMM-i9'!G:G,"")) -> 126
A34: 25 | B34: VSSIO7 | C34: - | D34: - | E34: - | F34: - | G34: - | H34: -
A35: 26 | B35: PL20C | C35: 7 | D35: - | E35: True_OF_PL20D | F35: - | G35: LDQ17 | H35: E5 | I35: =_xlfn.XLOOKUP(H35,'SO-DIMM-i9'!A:A,'SO-DIMM-i9'!B:B,_xlfn.XLOOKUP(H35,'SO-DIMM-i9'!H:H,'SO-DIMM-i9'!G:G,"")) -> 124
A36: 27 | B36: PL20B | C36: 7 | D36: - | E36: Comp_OF_PL20A | F36: TRUE | G36: LDQ17 | H36: E3 | I36: =_xlfn.XLOOKUP(H36,'SO-DIMM-i9'!A:A,'SO-DIMM-i9'!B:B,_xlfn.XLOOKUP(H36,'SO-DIMM-i9'!H:H,'SO-DIMM-i9'!G:G,"")) -> 137
A37: 28 | B37: VCCIO7 | C37: - | D37: - | E37: - | F37: - | G37: - | H37: -
A38: 29 | B38: PL20D | C38: 7 | D38: - | E38: Comp_OF_PL20C | F38: - | G38: LDQ17 | H38: F5 | I38: =_xlfn.XLOOKUP(H38,'SO-DIMM-i9'!A:A,'SO-DIMM-i9'!B:B,_xlfn.XLOOKUP(H38,'SO-DIMM-i9'!H:H,'SO-DIMM-i9'!G:G,"")) -> 120
A39: 30 | B39: PL23A | C39: 7 | D39: - | E39: True_OF_PL23B | F39: TRUE | G39: LDQ29 | H39: A2 | I39: =_xlfn.XLOOKUP(H39,'SO-DIMM-i9'!A:A,'SO-DIMM-i9'!B:B,_xlfn.XLOOKUP(H39,'SO-DIMM-i9'!H:H,'SO-DIMM-i9'!G:G,"")) -> 154
A40: 31 | B40: VSSIO7 | C40: - | D40: - | E40: - | F40: - | G40: - | H40: -
A41: 32 | B41: PL23C | C41: 7 | D41: VREF1_7 | E41: True_OF_PL23D | F41: - | G41: LDQ29 | H41: B2 | I41: =_xlfn.XLOOKUP(H41,'SO-DIMM-i9'!A:A,'SO-DIMM-i9'!B:B,_xlfn.XLOOKUP(H41,'SO-DIMM-i9'!H:H,'SO-DIMM-i9'!G:G,"")) -> 156
A42: 33 | B42: PL23B | C42: 7 | D42: - | E42: Comp_OF_PL23A | F42: TRUE | G42: LDQ29 | H42: B1 | I42: =_xlfn.XLOOKUP(H42,'SO-DIMM-i9'!A:A,'SO-DIMM-i9'!B:B,_xlfn.XLOOKUP(H42,'SO-DIMM-i9'!H:H,'SO-DIMM-i9'!G:G,"")) -> 143
A43: 34 | B43: VCCIO7 | C43: - | D43: - | E43: - | F43: - | G43: - | H43: -
...
